<?xml version="1.0" ?>
<robot xmlns:xacro="http://www.ros.org/wiki/xacro">

<xacro:property name="connect_offset" value="0.01" />
<xacro:property name="femur_offset_y" value="-0.125" />
<xacro:property name="femur_offset_z" value="-0.125" />

<xacro:property name="joint_lower_limit" value ="-${1.5}"/>
<xacro:property name="joint_upper_limit" value ="${1.5}"/>
<!-- <xacro:property name="joint_effort" value ="10000"/>
<xacro:property name="joint_velocity" value ="100"/> -->


<xacro:macro name="ardent" params="parent *origin">

    <joint name="j_ardent_attachment" type="fixed">
      <parent link="${parent}"/>
      <child link="body"/>
      <xacro:insert_block name="origin" />
    </joint> 

    <link name="body">
      <inertial>
        <origin xyz="0 0 0" />
        <mass value="6.8"/>
        <inertia ixx="3.1081800"  ixy="-0.25460189"  ixz="2.0318174" iyy="6.3787776" iyz="0.16417863" izz="5.3316425" />
      </inertial>
      <visual>
        <!--origin xyz="-0.0235 0 -0.03525" rpy="0 0 0" /-->
        <origin xyz="0 0 0" rpy="0 0 0" />
        <geometry>
          <cylinder radius="0.2" length="0.17"/>
          <!--box size="0.102 0.109 0.106" /-->
          <!-- <mesh filename="package://phantomx_description/meshes/body.STL"  scale="1 1 1"/> -->
        </geometry>
        <material name="Orange">
        <color rgba="12 12 12 1.0"/>
      </material>
      </visual>
      <collision>
        <origin xyz="0 0 0" rpy="0 0 0" />
        <geometry>
          <cylinder radius="0.2" length="0.17"/>
          <!-- <mesh filename="package://phantomx_description/meshes/body_coll.STL"  scale="1 1 1"/> -->
        </geometry>
      </collision>
    </link>

    <!-- Build Leg -->
    <xacro:leg_l xyz="0.175 -0.1  0.001116"  rpy="0 0 5.576" suffix="r1"/>
    <xacro:leg_l xyz="0 -0.2  0.001116"  rpy="0 0 -1.57" suffix="r2"/>
    <xacro:leg_l xyz="-0.175 -0.1  0.001116"  rpy="0 0 -2.62" suffix="r3"/>

    <xacro:leg_l xyz="0.175 0.1  0.001116"  rpy="0 0 0.52" suffix="l4"/>
    <xacro:leg_l xyz="0 0.2  0.001116"  rpy="0 0 1.57" suffix="l5"/>
    <xacro:leg_l xyz="-0.175 0.1  0.001116"  rpy="0 0 2.62" suffix="l6"/> 

</xacro:macro>

 <xacro:macro name="leg_l" params="xyz rpy suffix">
  <link name="coxa_${suffix}">
    <inertial>
      <origin xyz="0 0 0" rpy="0 0 0"  />
      <mass value="0.024357719"/>
     <inertia ixx="0.0051411124"  ixy="-0.00057530255"  ixz="-0.000024729049" iyy="0.0081915737" iyz="-0.000019223094" izz="0.0011379812" />
    </inertial>
    <visual>
      <origin xyz="0 0 0" rpy="0 0 0"  />
      <geometry>
        <box size="0.022 0.045 0.0325" />
          <!--<mesh filename="package://phantomx_description/meshes/connect.STL"  scale="1 1 1"/>-->
      </geometry>
      <material name="Grey">
        <color rgba="0.20 0.20 0.20 1.0"/>
      </material>
    </visual>
    <collision>
      <origin xyz="0 0 0" rpy="0 0 0"  />
      <geometry>
        <box size="0.022 0.045 0.0325" />
        <!-- <mesh filename="package://phantomx_description/meshes/connect_coll.STL"  scale="1 1 1"/> -->
      </geometry>
    </collision>
  </link>


  <link name="c2_${suffix}">
    <inertial>
      <origin xyz="0 0 0" rpy="0 0 0"  />
      <mass value="0.024357719"/>
     <inertia ixx="0.0051411124"  ixy="-0.00057530255"  ixz="-0.000024729049" iyy="0.0081915737" iyz="-0.000019223094" izz="0.0011379812" />
    </inertial>
    <visual>
      <origin xyz="0 0 0" rpy="0 0 0"  />
      <geometry>
        <box size="0.005 0.0325 0.0325" />
       <!-- <mesh filename="package://phantomx_description/meshes/connect.STL"  scale="1 1 1"/>-->
      </geometry>
      <material name="Orange">
        <color rgba="12 12 12 1.0"/>
      </material>
    </visual>
    <collision>
      <origin xyz="0 0 0" rpy="0 0 0"  />
      <geometry>
        <box size="0.005 0.0325 0.0325" />
        <!-- <mesh filename="package://phantomx_description/meshes/connect.STL"  scale="1 1 1"/>-->
      </geometry>
    </collision>
  </link>



  <link name="femur_${suffix}">
    <inertial>
      <origin xyz="1 0 0" rpy="0 0 0"  />
      <mass value="0.0286"/>
     <!-- <inertia ixx="0.000035572"  ixy="-0.000114256"  ixz="-0.000008584" iyy="0.000756486" iyz="-0.000001714" izz="0.000791714" /> -->
     <inertia ixx="0.00059"  ixy="-0.0"  ixz="-0.0" iyy="0.0" iyz="-0.0" izz="0.00059" /> 
    </inertial>
    <visual>
      <origin xyz="0.075 0 0" rpy="0 1.57 0"  />
      <geometry>
        <!-- <box size="0.022 0.25 0.0325" /> -->
        <cylinder  radius="0.015" length="0.15" />
        <!--<mesh filename="package://phantomx_description/meshes/thigh_l.STL"  scale="1 1 1"/>-->
      </geometry>
      <material name="Grey">
        <color rgba="0.20 0.20 0.20 1.0"/>
      </material>
    </visual>
    <collision>
      <origin xyz="0.075 0 0" rpy="0 1.57 0"  />
      <geometry>
        <cylinder  radius="0.015" length="0.15" />
        <!-- <mesh filename="package://phantomx_description/meshes/thigh_l_coll.STL"  scale="1 1 1"/> -->
      </geometry>
    </collision>
  </link>



  <link name="tibia_${suffix}">
    <inertial>
      <origin xyz="0 0 0" rpy="0 0 0"  />
      <mass value="0.0286"/>
      <!-- g/mm^2 -->
     <!-- <inertia ixx="35572"  ixy="-114256"  ixz="-8584" iyy="756486" iyz="-1714" izz="791714" /> -->
     <!-- <inertia ixx="0.000035572"  ixy="-0.000114256"  ixz="-0.000008584" iyy="0.000756486" iyz="-0.000001714" izz="0.000791714" /> -->
     <inertia ixx="0.00059"  ixy="-0.0"  ixz="-0.0" iyy="0.0" iyz="-0.0" izz="0.00059" /> 
    </inertial>
    <visual>
      <origin xyz="0.125 0 0" rpy="1.57 0 1.57"  />
      <geometry>
        <cylinder  radius="0.015" length="0.25" />
        <!-- <box size="0.022 0.25 0.0325" /> -->
        <!--<mesh filename="package://phantomx_description/meshes/tibia_l.STL"  scale="1 1 1"/>-->
      </geometry>
      <material name="Orange">
        <color rgba="12 12 12 1.0"/>
      </material>
    </visual>
    <collision>
      <origin xyz="0.125 0 0" rpy="1.57 0 1.57"  />
      <geometry>
        <cylinder  radius="0.015" length="0.25" />
        <!-- <mesh filename="package://phantomx_description/meshes/tibia_l_coll.STL"  scale="1 1 1"/> -->
      </geometry>
    </collision>
  </link>

<joint name="j_coxa_${suffix}" type="revolute">
    <parent link="body"/>
    <child link="coxa_${suffix}"/>
    <origin xyz="${xyz}" rpy="${rpy}" />
    <axis xyz="0 0 1" />
    <limit effort="30" velocity="0.5" lower="-3.14" upper="3.14" />
  </joint>

  <joint name="j_c2_${suffix}" type="fixed">
    <parent link="coxa_${suffix}"/>
    <child link="c2_${suffix}"/>
    <origin xyz="0.0135 0 0" rpy="0 0 0" />
    <limit effort="30" velocity="0.5" lower="-3.14" upper="3.14" />
  </joint>


  <joint name="j_femur_${suffix}" type="revolute">
    <parent link="c2_${suffix}"/>
    <child link="femur_${suffix}"/>
    <origin xyz="0 0 0" rpy=" 1.57 0 0" />
    <axis xyz="0 0 1" />
    <limit effort="30" velocity="0.5" lower="-3.14" upper="3.14" />
  </joint>

  <joint name="j_tibia_${suffix}" type="revolute">
    <parent link="femur_${suffix}"/>
    <child link="tibia_${suffix}"/>
    <origin xyz="0.125 0 0" rpy="0 0 0" />
    <axis xyz="0 0 1" />
    <limit effort="30" velocity="0.5" lower="-3.14" upper="3.14" />
  </joint>

   <!-- <gazebo reference="$tibia_${suffix}">
        <mu1>1</mu1>
        <mu2>1</mu2>
        <fdir1>1 0 0</fdir1>
        <minDepth>0.005</minDepth>
        <maxContacts>1</maxContacts>
            <collision name="$tibia_${suffix}_collision">
                <geometry>
                    <sphere>
                    <radius>0.02175</radius>
                </sphere>
                </geometry>

            <surface>
                <friction>
                    <torsional>
                            <coefficient>10</coefficient>
                            <use_patch_radius>true</use_patch_radius>
                            <surface_radius>0.05</surface_radius>
                            <patch_radius>0.01</patch_radius>
                    </torsional>
            </friction>
            <contact>
                <poissons_ratio>0.5</poissons_ratio>
                <elastic_modulus>1e8</elastic_modulus>
            </contact>
        </surface>
    </collision>
    </gazebo> -->

   <transmission name="t_coxa_${suffix}">
    <type>transmission_interface/SimpleTransmission</type>
    <joint name="j_coxa_${suffix}">
      <hardwareInterface>hardware_interface/EffortJointInterface</hardwareInterface>    
    </joint>
    <actuator name="m_coxa_${suffix}">
      <hardwareInterface>hardware_interface/EffortJointInterface</hardwareInterface>
      <mechanicalReduction>1</mechanicalReduction>
    </actuator>
  </transmission>


   <transmission name="t_femur_${suffix}">
    <type>transmission_interface/SimpleTransmission</type>
    <joint name="j_femur_${suffix}">
      <hardwareInterface>hardware_interface/EffortJointInterface</hardwareInterface>    
    </joint>
    <actuator name="m_femur_${suffix}">
      <hardwareInterface>hardware_interface/EffortJointInterface</hardwareInterface>
      <mechanicalReduction>1</mechanicalReduction>
    </actuator>
  </transmission>

   <transmission name="t_tibia_${suffix}">
    <type>transmission_interface/SimpleTransmission</type>
    <joint name="j_tibia_${suffix}">
      <hardwareInterface>hardware_interface/EffortJointInterface</hardwareInterface>
    </joint>
    <actuator name="m_tibia_${suffix}">
      <hardwareInterface>hardware_interface/EffortJointInterface</hardwareInterface>
      <mechanicalReduction>1</mechanicalReduction>
    </actuator>
  </transmission>

  <gazebo reference="body">
    <material>Gazebo/Orange</material>
  </gazebo>

  <gazebo reference="coxa_${suffix}">    
    <material>Gazebo/Black</material>
  </gazebo>

  <gazebo reference="c2_${suffix}">    
    <material>Gazebo/Orange</material>
  </gazebo>

  <gazebo reference="femur_${suffix}">    
    <material>Gazebo/Black</material>
  </gazebo>

  <gazebo reference="tibia_${suffix}">    
    <material>Gazebo/Orange</material>
  </gazebo>

  
</xacro:macro>





</robot>
