<?xml version="1.0" encoding="utf-8"?>
<!-- =================================================================================== -->
<!-- |    This document was autogenerated by xacro from ardent_quad.xacro              | -->
<!-- |    EDITING THIS FILE BY HAND IS NOT RECOMMENDED                                 | -->
<!-- =================================================================================== -->
<robot name="ardent" xmlns:xacro="http://www.ros.org/wiki/xacro">
  <!-- Size of square 'camera' box -->
  <!-- Link-->
  <joint name="camera_joint" type="fixed">
    <axis xyz="0 1 0"/>
    <origin rpy="0 0 0" xyz="0.2 0 0"/>
    <parent link="body"/>
    <child link="camera_link"/>
  </joint>
  <!-- Camera -->
  <link name="camera_link">
    <collision>
      <origin rpy="0 0 0" xyz="0 0 0"/>
      <geometry>
        <box size="0.05 0.05 0.05"/>
      </geometry>
    </collision>
    <visual>
      <origin rpy="0 0 0" xyz="0 0 0"/>
      <geometry>
        <box size="0.05 0.05 0.05"/>
      </geometry>
      <material name="red"/>
    </visual>
    <inertial>
      <mass value="1e-5"/>
      <origin rpy="0 0 0" xyz="0 0 0"/>
      <inertia ixx="1e-6" ixy="0" ixz="0" iyy="1e-6" iyz="0" izz="1e-6"/>
    </inertial>
  </link>
  <!-- generate an optical frame http://www.ros.org/reps/rep-0103.html#suffix-frames
        so that ros and opencv can operate on the camera frame correctly -->
  <joint name="camera_optical_joint" type="fixed">
    <!-- these values have to be these values otherwise the gazebo camera image
            won't be aligned properly with the frame it is supposedly originating from -->
    <origin rpy="-1.57079632679 0 -1.57079632679" xyz="0 0 0"/>
    <parent link="camera_link"/>
    <child link="camera_link_optical"/>
  </joint>
  <link name="camera_link_optical">
    </link>
  <!-- for more info visit: http://wiki.ros.org/urdf/Tutorials -->
  <link name="base_link"/>
  <joint name="j_ardent_attachment" type="fixed">
    <parent link="base_link"/>
    <child link="body"/>
    <origin rpy="0 0 0" xyz="0 0 0"/>
  </joint>
  <link name="body">
    <inertial>
      <origin xyz="0 0 0"/>
      <mass value="6.8"/>
      <inertia ixx="3.1081800" ixy="-0.25460189" ixz="2.0318174" iyy="6.3787776" iyz="0.16417863" izz="5.3316425"/>
    </inertial>
    <visual>
      <!--origin xyz="-0.0235 0 -0.03525" rpy="0 0 0" /-->
      <origin rpy="0 0 0" xyz="0 0 0"/>
      <geometry>
        <cylinder length="0.17" radius="0.2"/>
        <!--box size="0.102 0.109 0.106" /-->
        <!-- <mesh filename="package://phantomx_description/meshes/body.STL"  scale="1 1 1"/> -->
      </geometry>
      <material name="Orange">
        <color rgba="12 12 12 1.0"/>
      </material>
    </visual>
    <collision>
      <origin rpy="0 0 0" xyz="0 0 0"/>
      <geometry>
        <cylinder length="0.17" radius="0.2"/>
        <!-- <mesh filename="package://phantomx_description/meshes/body_coll.STL"  scale="1 1 1"/> -->
      </geometry>
    </collision>
  </link>
  <gazebo>
    <plugin filename="libgazebo_ros_p3d.so" name="p3d_base_controller">
      <alwaysOn>true</alwaysOn>
      <updateRate>50.0</updateRate>
      <bodyName>body</bodyName>
      <topicName>odom</topicName>
      <gaussianNoise>0.01</gaussianNoise>
      <frameNamespace>world</frameNamespace>
      <xyzOffsets> 0 0 0 </xyzOffsets>
      <rpyOffsets>0 0 0 </rpyOffsets>
    </plugin>
  </gazebo>
  <!-- <joint name="j_ardent_attachment" type="fixed">
      <parent link="${parent}"/>
      <child link="body"/>
      <xacro:insert_block name="origin" />
    </joint> -->
  <!-- <transmission name="t_ardent">
        <type>transmission_interface/SimpleTransmission</type>
        <joint name="j_ardent_attachment">
          <hardwareInterface>hardware_interface/EffortJointInterface</hardwareInterface>    
        </joint>
        <actuator name="j_ardent_attachment">
          <hardwareInterface>hardware_interface/EffortJointInterface</hardwareInterface>
          <mechanicalReduction>1</mechanicalReduction>
        </actuator>
      </transmission> -->
  <plugin filename="libgazebo_ros_imu.so" name="gazebo_ros_imu_plugin">
    <alwaysOn>true</alwaysOn>
    <bodyName>body</bodyName>
    <topicName>imu/data</topicName>
    <serviceName>imu/service</serviceName>
    <gaussianNoise>0.0</gaussianNoise>
    <updateRate>800.0</updateRate>
  </plugin>
  <link name="coxa_1">
    <inertial>
      <origin rpy="0 0 0" xyz="0 0 0"/>
      <mass value="0.024357719"/>
      <inertia ixx="0.0051411124" ixy="-0.00057530255" ixz="-0.000024729049" iyy="0.0081915737" iyz="-0.000019223094" izz="0.0011379812"/>
    </inertial>
    <visual>
      <origin rpy="0 0 0" xyz="0 0 0"/>
      <geometry>
        <box size="0.022 0.045 0.0325"/>
        <!--<mesh filename="package://phantomx_description/meshes/connect.STL"  scale="1 1 1"/>-->
      </geometry>
      <material name="Grey">
        <color rgba="0.20 0.20 0.20 1.0"/>
      </material>
    </visual>
    <collision>
      <origin rpy="0 0 0" xyz="0 0 0"/>
      <geometry>
        <box size="0.022 0.045 0.0325"/>
        <!-- <mesh filename="package://phantomx_description/meshes/connect_coll.STL"  scale="1 1 1"/> -->
      </geometry>
    </collision>
  </link>
  <link name="c2_1">
    <inertial>
      <origin rpy="0 0 0" xyz="0 0 0"/>
      <mass value="0.024357719"/>
      <inertia ixx="0.0051411124" ixy="-0.00057530255" ixz="-0.000024729049" iyy="0.0081915737" iyz="-0.000019223094" izz="0.0011379812"/>
    </inertial>
    <visual>
      <origin rpy="0 0 0" xyz="0 0 0"/>
      <geometry>
        <box size="0.005 0.0325 0.0325"/>
        <!-- <mesh filename="package://phantomx_description/meshes/connect.STL"  scale="1 1 1"/>-->
      </geometry>
      <material name="Orange">
        <color rgba="12 12 12 1.0"/>
      </material>
    </visual>
    <collision>
      <origin rpy="0 0 0" xyz="0 0 0"/>
      <geometry>
        <box size="0.005 0.0325 0.0325"/>
        <!-- <mesh filename="package://phantomx_description/meshes/connect.STL"  scale="1 1 1"/>-->
      </geometry>
    </collision>
  </link>
  <link name="femur_1">
    <inertial>
      <origin rpy="0 0 0" xyz="1 0 0"/>
      <mass value="0.0286"/>
      <!-- <inertia ixx="0.000035572"  ixy="-0.000114256"  ixz="-0.000008584" iyy="0.000756486" iyz="-0.000001714" izz="0.000791714" /> -->
      <inertia ixx="0.00059" ixy="-0.0" ixz="-0.0" iyy="0.0" iyz="-0.0" izz="0.00059"/>
    </inertial>
    <visual>
      <origin rpy="0 1.57 0" xyz="0.075 0 0"/>
      <geometry>
        <!-- <box size="0.022 0.25 0.0325" /> -->
        <cylinder length="0.15" radius="0.015"/>
        <!--<mesh filename="package://phantomx_description/meshes/thigh_l.STL"  scale="1 1 1"/>-->
      </geometry>
      <material name="Grey">
        <color rgba="0.20 0.20 0.20 1.0"/>
      </material>
    </visual>
    <collision>
      <origin rpy="0 1.57 0" xyz="0.075 0 0"/>
      <geometry>
        <cylinder length="0.15" radius="0.015"/>
        <!-- <mesh filename="package://phantomx_description/meshes/thigh_l_coll.STL"  scale="1 1 1"/> -->
      </geometry>
    </collision>
  </link>
  <link name="tibia_1">
    <inertial>
      <origin rpy="0 0 0" xyz="0 0 0"/>
      <mass value="0.0286"/>
      <!-- g/mm^2 -->
      <!-- <inertia ixx="35572"  ixy="-114256"  ixz="-8584" iyy="756486" iyz="-1714" izz="791714" /> -->
      <!-- <inertia ixx="0.000035572"  ixy="-0.000114256"  ixz="-0.000008584" iyy="0.000756486" iyz="-0.000001714" izz="0.000791714" /> -->
      <inertia ixx="0.00059" ixy="-0.0" ixz="-0.0" iyy="0.0" iyz="-0.0" izz="0.00059"/>
    </inertial>
    <visual>
      <origin rpy="1.57 0 1.57" xyz="0.125 0 0"/>
      <geometry>
        <cylinder length="0.25" radius="0.015"/>
        <!-- <box size="0.022 0.25 0.0325" /> -->
        <!--<mesh filename="package://phantomx_description/meshes/tibia_l.STL"  scale="1 1 1"/>-->
      </geometry>
      <material name="Orange">
        <color rgba="12 12 12 1.0"/>
      </material>
    </visual>
    <collision>
      <origin rpy="1.57 0 1.57" xyz="0.125 0 0"/>
      <geometry>
        <cylinder length="0.25" radius="0.015"/>
        <!-- <mesh filename="package://phantomx_description/meshes/tibia_l_coll.STL"  scale="1 1 1"/> -->
      </geometry>
    </collision>
  </link>
  <link name="contact_sensor_1">
    <inertial>
      <origin rpy="0 0 0" xyz="0 0 0"/>
      <mass value="0.005"/>
      <inertia ixx="1.28e-06" ixy="-0.0" ixz="-0.0" iyy="1.28e-06" iyz="-0.0" izz="1.28e-06"/>
    </inertial>
    <visual>
      <origin rpy="0 0 0" xyz="0 0 0"/>
      <geometry>
        <sphere radius="0.015"/>
        <!-- <box size="0.022 0.25 0.0325" /> -->
        <!--<mesh filename="package://phantomx_description/meshes/tibia_l.STL"  scale="1 1 1"/>-->
      </geometry>
      <material name="Black">
        <color rgba="1.0 0 0 0"/>
      </material>
    </visual>
    <collision>
      <origin rpy="0.0 0 0.0" xyz="0.0 0 0"/>
      <geometry>
        <sphere radius="0.015"/>
        <!-- <mesh filename="package://phantomx_description/meshes/tibia_l_coll.STL"  scale="1 1 1"/> -->
      </geometry>
    </collision>
  </link>
  <!-- Joint Definitions -->
  <joint name="j_coxa_1" type="revolute">
    <parent link="body"/>
    <child link="coxa_1"/>
    <origin rpy="0 0 5.576" xyz="0.175 -0.1  0.001116"/>
    <axis xyz="0 0 1"/>
    <limit effort="30" lower="-3.14" upper="3.14" velocity="0.5"/>
  </joint>
  <joint name="j_c2_1" type="fixed">
    <parent link="coxa_1"/>
    <child link="c2_1"/>
    <origin rpy="0 0 0" xyz="0.0135 0 0"/>
    <limit effort="30" lower="-3.14" upper="3.14" velocity="0.5"/>
  </joint>
  <joint name="j_femur_1" type="revolute">
    <parent link="c2_1"/>
    <child link="femur_1"/>
    <origin rpy=" 1.57 0 0" xyz="0 0 0"/>
    <axis xyz="0 0 1"/>
    <limit effort="30" lower="-3.14" upper="3.14" velocity="0.5"/>
  </joint>
  <joint name="j_tibia_1" type="revolute">
    <parent link="femur_1"/>
    <child link="tibia_1"/>
    <origin rpy="0 0 0" xyz="0.125 0 0"/>
    <axis xyz="0 0 1"/>
    <limit effort="30" lower="-3.14" upper="3.14" velocity="0.5"/>
  </joint>
  <joint name="j_contact_sensor_1" type="fixed">
    <parent link="tibia_1"/>
    <child link="contact_sensor_1"/>
    <origin rpy="0 0 0" xyz="0.25 0 0"/>
  </joint>
  <!-- <gazebo reference="$tibia_${suffix}">
        <mu1>1</mu1>
        <mu2>1</mu2>
        <fdir1>1 0 0</fdir1>
        <minDepth>0.005</minDepth>
        <maxContacts>1</maxContacts>
            <collision name="$tibia_${suffix}_collision">
                <geometry>
                    <sphere>
                    <radius>0.02175</radius>
                </sphere>
                </geometry>

            <surface>
                <friction>
                    <torsional>
                            <coefficient>10</coefficient>
                            <use_patch_radius>true</use_patch_radius>
                            <surface_radius>0.05</surface_radius>
                            <patch_radius>0.01</patch_radius>
                    </torsional>
            </friction>
            <contact>
                <poissons_ratio>0.5</poissons_ratio>
                <elastic_modulus>1e8</elastic_modulus>
            </contact>
        </surface>
    </collision>
    </gazebo> -->
  <!-- Force/Contact Sensor -->
  <!-- This should be added later to provide the force sensor feeback to the rest of the robot -->
  <gazebo reference="contact_sensor_1">
    <sensor name="contact_sensor_1" type="contact">
      <always_on>true</always_on>
      <update_rate>30</update_rate>
      <contact>
        <collision>contact_sensor_1_link_collision</collision>
      </contact>
      <plugin filename="libgazebo_ros_bumper.so" name="bumper0_plugin">
        <bumperTopicName>leg_1/contact_sensor_state</bumperTopicName>
        <frameName>contact_sensor_1</frameName>
      </plugin>
    </sensor>
  </gazebo>
  <!-- Transmissions -->
  <transmission name="t_coxa_1">
    <type>transmission_interface/SimpleTransmission</type>
    <joint name="j_coxa_1">
      <hardwareInterface>hardware_interface/EffortJointInterface</hardwareInterface>
    </joint>
    <actuator name="j_coxa_1">
      <hardwareInterface>hardware_interface/EffortJointInterface</hardwareInterface>
      <mechanicalReduction>1</mechanicalReduction>
    </actuator>
  </transmission>
  <transmission name="t_femur_1">
    <type>transmission_interface/SimpleTransmission</type>
    <joint name="j_femur_1">
      <hardwareInterface>hardware_interface/EffortJointInterface</hardwareInterface>
    </joint>
    <actuator name="j_femur_1">
      <hardwareInterface>hardware_interface/EffortJointInterface</hardwareInterface>
      <mechanicalReduction>1</mechanicalReduction>
    </actuator>
  </transmission>
  <transmission name="t_tibia_1">
    <type>transmission_interface/SimpleTransmission</type>
    <joint name="j_tibia_1">
      <hardwareInterface>hardware_interface/EffortJointInterface</hardwareInterface>
    </joint>
    <actuator name="j_tibia_1">
      <hardwareInterface>hardware_interface/EffortJointInterface</hardwareInterface>
      <mechanicalReduction>1</mechanicalReduction>
    </actuator>
  </transmission>
  <gazebo reference="body">
    <material>Gazebo/Orange</material>
  </gazebo>
  <gazebo reference="coxa_1">
    <material>Gazebo/Black</material>
  </gazebo>
  <gazebo reference="c2_1">
    <material>Gazebo/Orange</material>
  </gazebo>
  <gazebo reference="femur_1">
    <material>Gazebo/Black</material>
  </gazebo>
  <gazebo reference="tibia_1">
    <material>Gazebo/Orange</material>
  </gazebo>
  <gazebo reference="contact_sensor_1">
    <material>Gazebo/Black</material>
  </gazebo>
  <link name="coxa_2">
    <inertial>
      <origin rpy="0 0 0" xyz="0 0 0"/>
      <mass value="0.024357719"/>
      <inertia ixx="0.0051411124" ixy="-0.00057530255" ixz="-0.000024729049" iyy="0.0081915737" iyz="-0.000019223094" izz="0.0011379812"/>
    </inertial>
    <visual>
      <origin rpy="0 0 0" xyz="0 0 0"/>
      <geometry>
        <box size="0.022 0.045 0.0325"/>
        <!--<mesh filename="package://phantomx_description/meshes/connect.STL"  scale="1 1 1"/>-->
      </geometry>
      <material name="Grey">
        <color rgba="0.20 0.20 0.20 1.0"/>
      </material>
    </visual>
    <collision>
      <origin rpy="0 0 0" xyz="0 0 0"/>
      <geometry>
        <box size="0.022 0.045 0.0325"/>
        <!-- <mesh filename="package://phantomx_description/meshes/connect_coll.STL"  scale="1 1 1"/> -->
      </geometry>
    </collision>
  </link>
  <link name="c2_2">
    <inertial>
      <origin rpy="0 0 0" xyz="0 0 0"/>
      <mass value="0.024357719"/>
      <inertia ixx="0.0051411124" ixy="-0.00057530255" ixz="-0.000024729049" iyy="0.0081915737" iyz="-0.000019223094" izz="0.0011379812"/>
    </inertial>
    <visual>
      <origin rpy="0 0 0" xyz="0 0 0"/>
      <geometry>
        <box size="0.005 0.0325 0.0325"/>
        <!-- <mesh filename="package://phantomx_description/meshes/connect.STL"  scale="1 1 1"/>-->
      </geometry>
      <material name="Orange">
        <color rgba="12 12 12 1.0"/>
      </material>
    </visual>
    <collision>
      <origin rpy="0 0 0" xyz="0 0 0"/>
      <geometry>
        <box size="0.005 0.0325 0.0325"/>
        <!-- <mesh filename="package://phantomx_description/meshes/connect.STL"  scale="1 1 1"/>-->
      </geometry>
    </collision>
  </link>
  <link name="femur_2">
    <inertial>
      <origin rpy="0 0 0" xyz="1 0 0"/>
      <mass value="0.0286"/>
      <!-- <inertia ixx="0.000035572"  ixy="-0.000114256"  ixz="-0.000008584" iyy="0.000756486" iyz="-0.000001714" izz="0.000791714" /> -->
      <inertia ixx="0.00059" ixy="-0.0" ixz="-0.0" iyy="0.0" iyz="-0.0" izz="0.00059"/>
    </inertial>
    <visual>
      <origin rpy="0 1.57 0" xyz="0.075 0 0"/>
      <geometry>
        <!-- <box size="0.022 0.25 0.0325" /> -->
        <cylinder length="0.15" radius="0.015"/>
        <!--<mesh filename="package://phantomx_description/meshes/thigh_l.STL"  scale="1 1 1"/>-->
      </geometry>
      <material name="Grey">
        <color rgba="0.20 0.20 0.20 1.0"/>
      </material>
    </visual>
    <collision>
      <origin rpy="0 1.57 0" xyz="0.075 0 0"/>
      <geometry>
        <cylinder length="0.15" radius="0.015"/>
        <!-- <mesh filename="package://phantomx_description/meshes/thigh_l_coll.STL"  scale="1 1 1"/> -->
      </geometry>
    </collision>
  </link>
  <link name="tibia_2">
    <inertial>
      <origin rpy="0 0 0" xyz="0 0 0"/>
      <mass value="0.0286"/>
      <!-- g/mm^2 -->
      <!-- <inertia ixx="35572"  ixy="-114256"  ixz="-8584" iyy="756486" iyz="-1714" izz="791714" /> -->
      <!-- <inertia ixx="0.000035572"  ixy="-0.000114256"  ixz="-0.000008584" iyy="0.000756486" iyz="-0.000001714" izz="0.000791714" /> -->
      <inertia ixx="0.00059" ixy="-0.0" ixz="-0.0" iyy="0.0" iyz="-0.0" izz="0.00059"/>
    </inertial>
    <visual>
      <origin rpy="1.57 0 1.57" xyz="0.125 0 0"/>
      <geometry>
        <cylinder length="0.25" radius="0.015"/>
        <!-- <box size="0.022 0.25 0.0325" /> -->
        <!--<mesh filename="package://phantomx_description/meshes/tibia_l.STL"  scale="1 1 1"/>-->
      </geometry>
      <material name="Orange">
        <color rgba="12 12 12 1.0"/>
      </material>
    </visual>
    <collision>
      <origin rpy="1.57 0 1.57" xyz="0.125 0 0"/>
      <geometry>
        <cylinder length="0.25" radius="0.015"/>
        <!-- <mesh filename="package://phantomx_description/meshes/tibia_l_coll.STL"  scale="1 1 1"/> -->
      </geometry>
    </collision>
  </link>
  <link name="contact_sensor_2">
    <inertial>
      <origin rpy="0 0 0" xyz="0 0 0"/>
      <mass value="0.005"/>
      <inertia ixx="1.28e-06" ixy="-0.0" ixz="-0.0" iyy="1.28e-06" iyz="-0.0" izz="1.28e-06"/>
    </inertial>
    <visual>
      <origin rpy="0 0 0" xyz="0 0 0"/>
      <geometry>
        <sphere radius="0.015"/>
        <!-- <box size="0.022 0.25 0.0325" /> -->
        <!--<mesh filename="package://phantomx_description/meshes/tibia_l.STL"  scale="1 1 1"/>-->
      </geometry>
      <material name="Black">
        <color rgba="1.0 0 0 0"/>
      </material>
    </visual>
    <collision>
      <origin rpy="0.0 0 0.0" xyz="0.0 0 0"/>
      <geometry>
        <sphere radius="0.015"/>
        <!-- <mesh filename="package://phantomx_description/meshes/tibia_l_coll.STL"  scale="1 1 1"/> -->
      </geometry>
    </collision>
  </link>
  <!-- Joint Definitions -->
  <joint name="j_coxa_2" type="revolute">
    <parent link="body"/>
    <child link="coxa_2"/>
    <origin rpy="0 0 -2.62" xyz="-0.175 -0.1  0.001116"/>
    <axis xyz="0 0 1"/>
    <limit effort="30" lower="-3.14" upper="3.14" velocity="0.5"/>
  </joint>
  <joint name="j_c2_2" type="fixed">
    <parent link="coxa_2"/>
    <child link="c2_2"/>
    <origin rpy="0 0 0" xyz="0.0135 0 0"/>
    <limit effort="30" lower="-3.14" upper="3.14" velocity="0.5"/>
  </joint>
  <joint name="j_femur_2" type="revolute">
    <parent link="c2_2"/>
    <child link="femur_2"/>
    <origin rpy=" 1.57 0 0" xyz="0 0 0"/>
    <axis xyz="0 0 1"/>
    <limit effort="30" lower="-3.14" upper="3.14" velocity="0.5"/>
  </joint>
  <joint name="j_tibia_2" type="revolute">
    <parent link="femur_2"/>
    <child link="tibia_2"/>
    <origin rpy="0 0 0" xyz="0.125 0 0"/>
    <axis xyz="0 0 1"/>
    <limit effort="30" lower="-3.14" upper="3.14" velocity="0.5"/>
  </joint>
  <joint name="j_contact_sensor_2" type="fixed">
    <parent link="tibia_2"/>
    <child link="contact_sensor_2"/>
    <origin rpy="0 0 0" xyz="0.25 0 0"/>
  </joint>
  <!-- <gazebo reference="$tibia_${suffix}">
        <mu1>1</mu1>
        <mu2>1</mu2>
        <fdir1>1 0 0</fdir1>
        <minDepth>0.005</minDepth>
        <maxContacts>1</maxContacts>
            <collision name="$tibia_${suffix}_collision">
                <geometry>
                    <sphere>
                    <radius>0.02175</radius>
                </sphere>
                </geometry>

            <surface>
                <friction>
                    <torsional>
                            <coefficient>10</coefficient>
                            <use_patch_radius>true</use_patch_radius>
                            <surface_radius>0.05</surface_radius>
                            <patch_radius>0.01</patch_radius>
                    </torsional>
            </friction>
            <contact>
                <poissons_ratio>0.5</poissons_ratio>
                <elastic_modulus>1e8</elastic_modulus>
            </contact>
        </surface>
    </collision>
    </gazebo> -->
  <!-- Force/Contact Sensor -->
  <!-- This should be added later to provide the force sensor feeback to the rest of the robot -->
  <gazebo reference="contact_sensor_2">
    <sensor name="contact_sensor_2" type="contact">
      <always_on>true</always_on>
      <update_rate>30</update_rate>
      <contact>
        <collision>contact_sensor_2_link_collision</collision>
      </contact>
      <plugin filename="libgazebo_ros_bumper.so" name="bumper0_plugin">
        <bumperTopicName>leg_2/contact_sensor_state</bumperTopicName>
        <frameName>contact_sensor_2</frameName>
      </plugin>
    </sensor>
  </gazebo>
  <!-- Transmissions -->
  <transmission name="t_coxa_2">
    <type>transmission_interface/SimpleTransmission</type>
    <joint name="j_coxa_2">
      <hardwareInterface>hardware_interface/EffortJointInterface</hardwareInterface>
    </joint>
    <actuator name="j_coxa_2">
      <hardwareInterface>hardware_interface/EffortJointInterface</hardwareInterface>
      <mechanicalReduction>1</mechanicalReduction>
    </actuator>
  </transmission>
  <transmission name="t_femur_2">
    <type>transmission_interface/SimpleTransmission</type>
    <joint name="j_femur_2">
      <hardwareInterface>hardware_interface/EffortJointInterface</hardwareInterface>
    </joint>
    <actuator name="j_femur_2">
      <hardwareInterface>hardware_interface/EffortJointInterface</hardwareInterface>
      <mechanicalReduction>1</mechanicalReduction>
    </actuator>
  </transmission>
  <transmission name="t_tibia_2">
    <type>transmission_interface/SimpleTransmission</type>
    <joint name="j_tibia_2">
      <hardwareInterface>hardware_interface/EffortJointInterface</hardwareInterface>
    </joint>
    <actuator name="j_tibia_2">
      <hardwareInterface>hardware_interface/EffortJointInterface</hardwareInterface>
      <mechanicalReduction>1</mechanicalReduction>
    </actuator>
  </transmission>
  <gazebo reference="body">
    <material>Gazebo/Orange</material>
  </gazebo>
  <gazebo reference="coxa_2">
    <material>Gazebo/Black</material>
  </gazebo>
  <gazebo reference="c2_2">
    <material>Gazebo/Orange</material>
  </gazebo>
  <gazebo reference="femur_2">
    <material>Gazebo/Black</material>
  </gazebo>
  <gazebo reference="tibia_2">
    <material>Gazebo/Orange</material>
  </gazebo>
  <gazebo reference="contact_sensor_2">
    <material>Gazebo/Black</material>
  </gazebo>
  <link name="coxa_3">
    <inertial>
      <origin rpy="0 0 0" xyz="0 0 0"/>
      <mass value="0.024357719"/>
      <inertia ixx="0.0051411124" ixy="-0.00057530255" ixz="-0.000024729049" iyy="0.0081915737" iyz="-0.000019223094" izz="0.0011379812"/>
    </inertial>
    <visual>
      <origin rpy="0 0 0" xyz="0 0 0"/>
      <geometry>
        <box size="0.022 0.045 0.0325"/>
        <!--<mesh filename="package://phantomx_description/meshes/connect.STL"  scale="1 1 1"/>-->
      </geometry>
      <material name="Grey">
        <color rgba="0.20 0.20 0.20 1.0"/>
      </material>
    </visual>
    <collision>
      <origin rpy="0 0 0" xyz="0 0 0"/>
      <geometry>
        <box size="0.022 0.045 0.0325"/>
        <!-- <mesh filename="package://phantomx_description/meshes/connect_coll.STL"  scale="1 1 1"/> -->
      </geometry>
    </collision>
  </link>
  <link name="c2_3">
    <inertial>
      <origin rpy="0 0 0" xyz="0 0 0"/>
      <mass value="0.024357719"/>
      <inertia ixx="0.0051411124" ixy="-0.00057530255" ixz="-0.000024729049" iyy="0.0081915737" iyz="-0.000019223094" izz="0.0011379812"/>
    </inertial>
    <visual>
      <origin rpy="0 0 0" xyz="0 0 0"/>
      <geometry>
        <box size="0.005 0.0325 0.0325"/>
        <!-- <mesh filename="package://phantomx_description/meshes/connect.STL"  scale="1 1 1"/>-->
      </geometry>
      <material name="Orange">
        <color rgba="12 12 12 1.0"/>
      </material>
    </visual>
    <collision>
      <origin rpy="0 0 0" xyz="0 0 0"/>
      <geometry>
        <box size="0.005 0.0325 0.0325"/>
        <!-- <mesh filename="package://phantomx_description/meshes/connect.STL"  scale="1 1 1"/>-->
      </geometry>
    </collision>
  </link>
  <link name="femur_3">
    <inertial>
      <origin rpy="0 0 0" xyz="1 0 0"/>
      <mass value="0.0286"/>
      <!-- <inertia ixx="0.000035572"  ixy="-0.000114256"  ixz="-0.000008584" iyy="0.000756486" iyz="-0.000001714" izz="0.000791714" /> -->
      <inertia ixx="0.00059" ixy="-0.0" ixz="-0.0" iyy="0.0" iyz="-0.0" izz="0.00059"/>
    </inertial>
    <visual>
      <origin rpy="0 1.57 0" xyz="0.075 0 0"/>
      <geometry>
        <!-- <box size="0.022 0.25 0.0325" /> -->
        <cylinder length="0.15" radius="0.015"/>
        <!--<mesh filename="package://phantomx_description/meshes/thigh_l.STL"  scale="1 1 1"/>-->
      </geometry>
      <material name="Grey">
        <color rgba="0.20 0.20 0.20 1.0"/>
      </material>
    </visual>
    <collision>
      <origin rpy="0 1.57 0" xyz="0.075 0 0"/>
      <geometry>
        <cylinder length="0.15" radius="0.015"/>
        <!-- <mesh filename="package://phantomx_description/meshes/thigh_l_coll.STL"  scale="1 1 1"/> -->
      </geometry>
    </collision>
  </link>
  <link name="tibia_3">
    <inertial>
      <origin rpy="0 0 0" xyz="0 0 0"/>
      <mass value="0.0286"/>
      <!-- g/mm^2 -->
      <!-- <inertia ixx="35572"  ixy="-114256"  ixz="-8584" iyy="756486" iyz="-1714" izz="791714" /> -->
      <!-- <inertia ixx="0.000035572"  ixy="-0.000114256"  ixz="-0.000008584" iyy="0.000756486" iyz="-0.000001714" izz="0.000791714" /> -->
      <inertia ixx="0.00059" ixy="-0.0" ixz="-0.0" iyy="0.0" iyz="-0.0" izz="0.00059"/>
    </inertial>
    <visual>
      <origin rpy="1.57 0 1.57" xyz="0.125 0 0"/>
      <geometry>
        <cylinder length="0.25" radius="0.015"/>
        <!-- <box size="0.022 0.25 0.0325" /> -->
        <!--<mesh filename="package://phantomx_description/meshes/tibia_l.STL"  scale="1 1 1"/>-->
      </geometry>
      <material name="Orange">
        <color rgba="12 12 12 1.0"/>
      </material>
    </visual>
    <collision>
      <origin rpy="1.57 0 1.57" xyz="0.125 0 0"/>
      <geometry>
        <cylinder length="0.25" radius="0.015"/>
        <!-- <mesh filename="package://phantomx_description/meshes/tibia_l_coll.STL"  scale="1 1 1"/> -->
      </geometry>
    </collision>
  </link>
  <link name="contact_sensor_3">
    <inertial>
      <origin rpy="0 0 0" xyz="0 0 0"/>
      <mass value="0.005"/>
      <inertia ixx="1.28e-06" ixy="-0.0" ixz="-0.0" iyy="1.28e-06" iyz="-0.0" izz="1.28e-06"/>
    </inertial>
    <visual>
      <origin rpy="0 0 0" xyz="0 0 0"/>
      <geometry>
        <sphere radius="0.015"/>
        <!-- <box size="0.022 0.25 0.0325" /> -->
        <!--<mesh filename="package://phantomx_description/meshes/tibia_l.STL"  scale="1 1 1"/>-->
      </geometry>
      <material name="Black">
        <color rgba="1.0 0 0 0"/>
      </material>
    </visual>
    <collision>
      <origin rpy="0.0 0 0.0" xyz="0.0 0 0"/>
      <geometry>
        <sphere radius="0.015"/>
        <!-- <mesh filename="package://phantomx_description/meshes/tibia_l_coll.STL"  scale="1 1 1"/> -->
      </geometry>
    </collision>
  </link>
  <!-- Joint Definitions -->
  <joint name="j_coxa_3" type="revolute">
    <parent link="body"/>
    <child link="coxa_3"/>
    <origin rpy="0 0 0.52" xyz="0.175 0.1  0.001116"/>
    <axis xyz="0 0 1"/>
    <limit effort="30" lower="-3.14" upper="3.14" velocity="0.5"/>
  </joint>
  <joint name="j_c2_3" type="fixed">
    <parent link="coxa_3"/>
    <child link="c2_3"/>
    <origin rpy="0 0 0" xyz="0.0135 0 0"/>
    <limit effort="30" lower="-3.14" upper="3.14" velocity="0.5"/>
  </joint>
  <joint name="j_femur_3" type="revolute">
    <parent link="c2_3"/>
    <child link="femur_3"/>
    <origin rpy=" 1.57 0 0" xyz="0 0 0"/>
    <axis xyz="0 0 1"/>
    <limit effort="30" lower="-3.14" upper="3.14" velocity="0.5"/>
  </joint>
  <joint name="j_tibia_3" type="revolute">
    <parent link="femur_3"/>
    <child link="tibia_3"/>
    <origin rpy="0 0 0" xyz="0.125 0 0"/>
    <axis xyz="0 0 1"/>
    <limit effort="30" lower="-3.14" upper="3.14" velocity="0.5"/>
  </joint>
  <joint name="j_contact_sensor_3" type="fixed">
    <parent link="tibia_3"/>
    <child link="contact_sensor_3"/>
    <origin rpy="0 0 0" xyz="0.25 0 0"/>
  </joint>
  <!-- <gazebo reference="$tibia_${suffix}">
        <mu1>1</mu1>
        <mu2>1</mu2>
        <fdir1>1 0 0</fdir1>
        <minDepth>0.005</minDepth>
        <maxContacts>1</maxContacts>
            <collision name="$tibia_${suffix}_collision">
                <geometry>
                    <sphere>
                    <radius>0.02175</radius>
                </sphere>
                </geometry>

            <surface>
                <friction>
                    <torsional>
                            <coefficient>10</coefficient>
                            <use_patch_radius>true</use_patch_radius>
                            <surface_radius>0.05</surface_radius>
                            <patch_radius>0.01</patch_radius>
                    </torsional>
            </friction>
            <contact>
                <poissons_ratio>0.5</poissons_ratio>
                <elastic_modulus>1e8</elastic_modulus>
            </contact>
        </surface>
    </collision>
    </gazebo> -->
  <!-- Force/Contact Sensor -->
  <!-- This should be added later to provide the force sensor feeback to the rest of the robot -->
  <gazebo reference="contact_sensor_3">
    <sensor name="contact_sensor_3" type="contact">
      <always_on>true</always_on>
      <update_rate>30</update_rate>
      <contact>
        <collision>contact_sensor_3_link_collision</collision>
      </contact>
      <plugin filename="libgazebo_ros_bumper.so" name="bumper0_plugin">
        <bumperTopicName>leg_3/contact_sensor_state</bumperTopicName>
        <frameName>contact_sensor_3</frameName>
      </plugin>
    </sensor>
  </gazebo>
  <!-- Transmissions -->
  <transmission name="t_coxa_3">
    <type>transmission_interface/SimpleTransmission</type>
    <joint name="j_coxa_3">
      <hardwareInterface>hardware_interface/EffortJointInterface</hardwareInterface>
    </joint>
    <actuator name="j_coxa_3">
      <hardwareInterface>hardware_interface/EffortJointInterface</hardwareInterface>
      <mechanicalReduction>1</mechanicalReduction>
    </actuator>
  </transmission>
  <transmission name="t_femur_3">
    <type>transmission_interface/SimpleTransmission</type>
    <joint name="j_femur_3">
      <hardwareInterface>hardware_interface/EffortJointInterface</hardwareInterface>
    </joint>
    <actuator name="j_femur_3">
      <hardwareInterface>hardware_interface/EffortJointInterface</hardwareInterface>
      <mechanicalReduction>1</mechanicalReduction>
    </actuator>
  </transmission>
  <transmission name="t_tibia_3">
    <type>transmission_interface/SimpleTransmission</type>
    <joint name="j_tibia_3">
      <hardwareInterface>hardware_interface/EffortJointInterface</hardwareInterface>
    </joint>
    <actuator name="j_tibia_3">
      <hardwareInterface>hardware_interface/EffortJointInterface</hardwareInterface>
      <mechanicalReduction>1</mechanicalReduction>
    </actuator>
  </transmission>
  <gazebo reference="body">
    <material>Gazebo/Orange</material>
  </gazebo>
  <gazebo reference="coxa_3">
    <material>Gazebo/Black</material>
  </gazebo>
  <gazebo reference="c2_3">
    <material>Gazebo/Orange</material>
  </gazebo>
  <gazebo reference="femur_3">
    <material>Gazebo/Black</material>
  </gazebo>
  <gazebo reference="tibia_3">
    <material>Gazebo/Orange</material>
  </gazebo>
  <gazebo reference="contact_sensor_3">
    <material>Gazebo/Black</material>
  </gazebo>
  <link name="coxa_4">
    <inertial>
      <origin rpy="0 0 0" xyz="0 0 0"/>
      <mass value="0.024357719"/>
      <inertia ixx="0.0051411124" ixy="-0.00057530255" ixz="-0.000024729049" iyy="0.0081915737" iyz="-0.000019223094" izz="0.0011379812"/>
    </inertial>
    <visual>
      <origin rpy="0 0 0" xyz="0 0 0"/>
      <geometry>
        <box size="0.022 0.045 0.0325"/>
        <!--<mesh filename="package://phantomx_description/meshes/connect.STL"  scale="1 1 1"/>-->
      </geometry>
      <material name="Grey">
        <color rgba="0.20 0.20 0.20 1.0"/>
      </material>
    </visual>
    <collision>
      <origin rpy="0 0 0" xyz="0 0 0"/>
      <geometry>
        <box size="0.022 0.045 0.0325"/>
        <!-- <mesh filename="package://phantomx_description/meshes/connect_coll.STL"  scale="1 1 1"/> -->
      </geometry>
    </collision>
  </link>
  <link name="c2_4">
    <inertial>
      <origin rpy="0 0 0" xyz="0 0 0"/>
      <mass value="0.024357719"/>
      <inertia ixx="0.0051411124" ixy="-0.00057530255" ixz="-0.000024729049" iyy="0.0081915737" iyz="-0.000019223094" izz="0.0011379812"/>
    </inertial>
    <visual>
      <origin rpy="0 0 0" xyz="0 0 0"/>
      <geometry>
        <box size="0.005 0.0325 0.0325"/>
        <!-- <mesh filename="package://phantomx_description/meshes/connect.STL"  scale="1 1 1"/>-->
      </geometry>
      <material name="Orange">
        <color rgba="12 12 12 1.0"/>
      </material>
    </visual>
    <collision>
      <origin rpy="0 0 0" xyz="0 0 0"/>
      <geometry>
        <box size="0.005 0.0325 0.0325"/>
        <!-- <mesh filename="package://phantomx_description/meshes/connect.STL"  scale="1 1 1"/>-->
      </geometry>
    </collision>
  </link>
  <link name="femur_4">
    <inertial>
      <origin rpy="0 0 0" xyz="1 0 0"/>
      <mass value="0.0286"/>
      <!-- <inertia ixx="0.000035572"  ixy="-0.000114256"  ixz="-0.000008584" iyy="0.000756486" iyz="-0.000001714" izz="0.000791714" /> -->
      <inertia ixx="0.00059" ixy="-0.0" ixz="-0.0" iyy="0.0" iyz="-0.0" izz="0.00059"/>
    </inertial>
    <visual>
      <origin rpy="0 1.57 0" xyz="0.075 0 0"/>
      <geometry>
        <!-- <box size="0.022 0.25 0.0325" /> -->
        <cylinder length="0.15" radius="0.015"/>
        <!--<mesh filename="package://phantomx_description/meshes/thigh_l.STL"  scale="1 1 1"/>-->
      </geometry>
      <material name="Grey">
        <color rgba="0.20 0.20 0.20 1.0"/>
      </material>
    </visual>
    <collision>
      <origin rpy="0 1.57 0" xyz="0.075 0 0"/>
      <geometry>
        <cylinder length="0.15" radius="0.015"/>
        <!-- <mesh filename="package://phantomx_description/meshes/thigh_l_coll.STL"  scale="1 1 1"/> -->
      </geometry>
    </collision>
  </link>
  <link name="tibia_4">
    <inertial>
      <origin rpy="0 0 0" xyz="0 0 0"/>
      <mass value="0.0286"/>
      <!-- g/mm^2 -->
      <!-- <inertia ixx="35572"  ixy="-114256"  ixz="-8584" iyy="756486" iyz="-1714" izz="791714" /> -->
      <!-- <inertia ixx="0.000035572"  ixy="-0.000114256"  ixz="-0.000008584" iyy="0.000756486" iyz="-0.000001714" izz="0.000791714" /> -->
      <inertia ixx="0.00059" ixy="-0.0" ixz="-0.0" iyy="0.0" iyz="-0.0" izz="0.00059"/>
    </inertial>
    <visual>
      <origin rpy="1.57 0 1.57" xyz="0.125 0 0"/>
      <geometry>
        <cylinder length="0.25" radius="0.015"/>
        <!-- <box size="0.022 0.25 0.0325" /> -->
        <!--<mesh filename="package://phantomx_description/meshes/tibia_l.STL"  scale="1 1 1"/>-->
      </geometry>
      <material name="Orange">
        <color rgba="12 12 12 1.0"/>
      </material>
    </visual>
    <collision>
      <origin rpy="1.57 0 1.57" xyz="0.125 0 0"/>
      <geometry>
        <cylinder length="0.25" radius="0.015"/>
        <!-- <mesh filename="package://phantomx_description/meshes/tibia_l_coll.STL"  scale="1 1 1"/> -->
      </geometry>
    </collision>
  </link>
  <link name="contact_sensor_4">
    <inertial>
      <origin rpy="0 0 0" xyz="0 0 0"/>
      <mass value="0.005"/>
      <inertia ixx="1.28e-06" ixy="-0.0" ixz="-0.0" iyy="1.28e-06" iyz="-0.0" izz="1.28e-06"/>
    </inertial>
    <visual>
      <origin rpy="0 0 0" xyz="0 0 0"/>
      <geometry>
        <sphere radius="0.015"/>
        <!-- <box size="0.022 0.25 0.0325" /> -->
        <!--<mesh filename="package://phantomx_description/meshes/tibia_l.STL"  scale="1 1 1"/>-->
      </geometry>
      <material name="Black">
        <color rgba="1.0 0 0 0"/>
      </material>
    </visual>
    <collision>
      <origin rpy="0.0 0 0.0" xyz="0.0 0 0"/>
      <geometry>
        <sphere radius="0.015"/>
        <!-- <mesh filename="package://phantomx_description/meshes/tibia_l_coll.STL"  scale="1 1 1"/> -->
      </geometry>
    </collision>
  </link>
  <!-- Joint Definitions -->
  <joint name="j_coxa_4" type="revolute">
    <parent link="body"/>
    <child link="coxa_4"/>
    <origin rpy="0 0 2.62" xyz="-0.175 0.1  0.001116"/>
    <axis xyz="0 0 1"/>
    <limit effort="30" lower="-3.14" upper="3.14" velocity="0.5"/>
  </joint>
  <joint name="j_c2_4" type="fixed">
    <parent link="coxa_4"/>
    <child link="c2_4"/>
    <origin rpy="0 0 0" xyz="0.0135 0 0"/>
    <limit effort="30" lower="-3.14" upper="3.14" velocity="0.5"/>
  </joint>
  <joint name="j_femur_4" type="revolute">
    <parent link="c2_4"/>
    <child link="femur_4"/>
    <origin rpy=" 1.57 0 0" xyz="0 0 0"/>
    <axis xyz="0 0 1"/>
    <limit effort="30" lower="-3.14" upper="3.14" velocity="0.5"/>
  </joint>
  <joint name="j_tibia_4" type="revolute">
    <parent link="femur_4"/>
    <child link="tibia_4"/>
    <origin rpy="0 0 0" xyz="0.125 0 0"/>
    <axis xyz="0 0 1"/>
    <limit effort="30" lower="-3.14" upper="3.14" velocity="0.5"/>
  </joint>
  <joint name="j_contact_sensor_4" type="fixed">
    <parent link="tibia_4"/>
    <child link="contact_sensor_4"/>
    <origin rpy="0 0 0" xyz="0.25 0 0"/>
  </joint>
  <!-- <gazebo reference="$tibia_${suffix}">
        <mu1>1</mu1>
        <mu2>1</mu2>
        <fdir1>1 0 0</fdir1>
        <minDepth>0.005</minDepth>
        <maxContacts>1</maxContacts>
            <collision name="$tibia_${suffix}_collision">
                <geometry>
                    <sphere>
                    <radius>0.02175</radius>
                </sphere>
                </geometry>

            <surface>
                <friction>
                    <torsional>
                            <coefficient>10</coefficient>
                            <use_patch_radius>true</use_patch_radius>
                            <surface_radius>0.05</surface_radius>
                            <patch_radius>0.01</patch_radius>
                    </torsional>
            </friction>
            <contact>
                <poissons_ratio>0.5</poissons_ratio>
                <elastic_modulus>1e8</elastic_modulus>
            </contact>
        </surface>
    </collision>
    </gazebo> -->
  <!-- Force/Contact Sensor -->
  <!-- This should be added later to provide the force sensor feeback to the rest of the robot -->
  <gazebo reference="contact_sensor_4">
    <sensor name="contact_sensor_4" type="contact">
      <always_on>true</always_on>
      <update_rate>30</update_rate>
      <contact>
        <collision>contact_sensor_4_link_collision</collision>
      </contact>
      <plugin filename="libgazebo_ros_bumper.so" name="bumper0_plugin">
        <bumperTopicName>leg_4/contact_sensor_state</bumperTopicName>
        <frameName>contact_sensor_4</frameName>
      </plugin>
    </sensor>
  </gazebo>
  <!-- Transmissions -->
  <transmission name="t_coxa_4">
    <type>transmission_interface/SimpleTransmission</type>
    <joint name="j_coxa_4">
      <hardwareInterface>hardware_interface/EffortJointInterface</hardwareInterface>
    </joint>
    <actuator name="j_coxa_4">
      <hardwareInterface>hardware_interface/EffortJointInterface</hardwareInterface>
      <mechanicalReduction>1</mechanicalReduction>
    </actuator>
  </transmission>
  <transmission name="t_femur_4">
    <type>transmission_interface/SimpleTransmission</type>
    <joint name="j_femur_4">
      <hardwareInterface>hardware_interface/EffortJointInterface</hardwareInterface>
    </joint>
    <actuator name="j_femur_4">
      <hardwareInterface>hardware_interface/EffortJointInterface</hardwareInterface>
      <mechanicalReduction>1</mechanicalReduction>
    </actuator>
  </transmission>
  <transmission name="t_tibia_4">
    <type>transmission_interface/SimpleTransmission</type>
    <joint name="j_tibia_4">
      <hardwareInterface>hardware_interface/EffortJointInterface</hardwareInterface>
    </joint>
    <actuator name="j_tibia_4">
      <hardwareInterface>hardware_interface/EffortJointInterface</hardwareInterface>
      <mechanicalReduction>1</mechanicalReduction>
    </actuator>
  </transmission>
  <gazebo reference="body">
    <material>Gazebo/Orange</material>
  </gazebo>
  <gazebo reference="coxa_4">
    <material>Gazebo/Black</material>
  </gazebo>
  <gazebo reference="c2_4">
    <material>Gazebo/Orange</material>
  </gazebo>
  <gazebo reference="femur_4">
    <material>Gazebo/Black</material>
  </gazebo>
  <gazebo reference="tibia_4">
    <material>Gazebo/Orange</material>
  </gazebo>
  <gazebo reference="contact_sensor_4">
    <material>Gazebo/Black</material>
  </gazebo>
  <!-- <gazebo>
    <controller:gazebo_ros_controller_manager plugin="libgazebo_ros_controller_manager.so" name="gazebo_ros_controller_manager">
        <alwaysOn>true</alwaysOn>
        <updateRate>1000.0</updateRate>
        <robotParam>robot_description</robotParam>
        <robotNamespace>/</robotNamespace>
    </controller:gazebo_ros_controller_manager>
  </gazebo> -->
  <gazebo>
    <plugin filename="libgazebo_ros_control.so" name="gazebo_ros_control"> 
    </plugin>
  </gazebo>
</robot>

